2019-02-27 07:28:48,761: http-jsonrpc listening at 127.0.0.1:5383
2019-02-27 07:28:48,831: Traceback (most recent call last):
  File ".\relaykeysd.py", line 265, in do_main
    with SerialCls(devicepath, BAUD, rtscts=1) as ser:
  File "C:\Users\wwade\AppData\Local\Programs\Python\Python37\lib\site-packages\serial\serialwin32.py", line 31, in __init__
    super(Serial, self).__init__(*args, **kwargs)
  File "C:\Users\wwade\AppData\Local\Programs\Python\Python37\lib\site-packages\serial\serialutil.py", line 240, in __init__
    self.open()
  File "C:\Users\wwade\AppData\Local\Programs\Python\Python37\lib\site-packages\serial\serialwin32.py", line 62, in open
    raise SerialException("could not open port {!r}: {!r}".format(self.portstr, ctypes.WinError()))
serial.serialutil.SerialException: could not open port 'COM8': PermissionError(13, 'Access is denied.', None, 5)

2019-02-27 07:28:48,841: Will retry in 10 seconds
2019-02-27 07:28:58,856: Traceback (most recent call last):
  File ".\relaykeysd.py", line 265, in do_main
    with SerialCls(devicepath, BAUD, rtscts=1) as ser:
  File "C:\Users\wwade\AppData\Local\Programs\Python\Python37\lib\site-packages\serial\serialwin32.py", line 31, in __init__
    super(Serial, self).__init__(*args, **kwargs)
  File "C:\Users\wwade\AppData\Local\Programs\Python\Python37\lib\site-packages\serial\serialutil.py", line 240, in __init__
    self.open()
  File "C:\Users\wwade\AppData\Local\Programs\Python\Python37\lib\site-packages\serial\serialwin32.py", line 62, in open
    raise SerialException("could not open port {!r}: {!r}".format(self.portstr, ctypes.WinError()))
serial.serialutil.SerialException: could not open port 'COM8': PermissionError(13, 'Access is denied.', None, 5)

2019-02-27 07:28:58,856: Will retry in 10 seconds
2019-02-27 07:36:03,096: http-jsonrpc listening at 127.0.0.1:5383
2019-02-27 07:36:03,112: Traceback (most recent call last):
  File "relaykeysd.py", line 265, in do_main
    with SerialCls(devicepath, BAUD, rtscts=1) as ser:
  File "C:\Users\wwade\AppData\Local\Programs\Python\Python37\lib\site-packages\serial\serialwin32.py", line 31, in __init__
    super(Serial, self).__init__(*args, **kwargs)
  File "C:\Users\wwade\AppData\Local\Programs\Python\Python37\lib\site-packages\serial\serialutil.py", line 240, in __init__
    self.open()
  File "C:\Users\wwade\AppData\Local\Programs\Python\Python37\lib\site-packages\serial\serialwin32.py", line 62, in open
    raise SerialException("could not open port {!r}: {!r}".format(self.portstr, ctypes.WinError()))
serial.serialutil.SerialException: could not open port 'COM8': PermissionError(13, 'Access is denied.', None, 5)

2019-02-27 07:36:03,112: Will retry in 10 seconds
2019-02-27 07:36:13,113: Traceback (most recent call last):
  File "relaykeysd.py", line 265, in do_main
    with SerialCls(devicepath, BAUD, rtscts=1) as ser:
  File "C:\Users\wwade\AppData\Local\Programs\Python\Python37\lib\site-packages\serial\serialwin32.py", line 31, in __init__
    super(Serial, self).__init__(*args, **kwargs)
  File "C:\Users\wwade\AppData\Local\Programs\Python\Python37\lib\site-packages\serial\serialutil.py", line 240, in __init__
    self.open()
  File "C:\Users\wwade\AppData\Local\Programs\Python\Python37\lib\site-packages\serial\serialwin32.py", line 62, in open
    raise SerialException("could not open port {!r}: {!r}".format(self.portstr, ctypes.WinError()))
serial.serialutil.SerialException: could not open port 'COM8': PermissionError(13, 'Access is denied.', None, 5)

2019-02-27 07:36:13,113: Will retry in 10 seconds
2019-02-27 07:36:23,116: Traceback (most recent call last):
  File "relaykeysd.py", line 265, in do_main
    with SerialCls(devicepath, BAUD, rtscts=1) as ser:
  File "C:\Users\wwade\AppData\Local\Programs\Python\Python37\lib\site-packages\serial\serialwin32.py", line 31, in __init__
    super(Serial, self).__init__(*args, **kwargs)
  File "C:\Users\wwade\AppData\Local\Programs\Python\Python37\lib\site-packages\serial\serialutil.py", line 240, in __init__
    self.open()
  File "C:\Users\wwade\AppData\Local\Programs\Python\Python37\lib\site-packages\serial\serialwin32.py", line 62, in open
    raise SerialException("could not open port {!r}: {!r}".format(self.portstr, ctypes.WinError()))
serial.serialutil.SerialException: could not open port 'COM8': PermissionError(13, 'Access is denied.', None, 5)

2019-02-27 07:36:23,116: Will retry in 10 seconds
2019-02-27 07:36:33,130: Traceback (most recent call last):
  File "relaykeysd.py", line 265, in do_main
    with SerialCls(devicepath, BAUD, rtscts=1) as ser:
  File "C:\Users\wwade\AppData\Local\Programs\Python\Python37\lib\site-packages\serial\serialwin32.py", line 31, in __init__
    super(Serial, self).__init__(*args, **kwargs)
  File "C:\Users\wwade\AppData\Local\Programs\Python\Python37\lib\site-packages\serial\serialutil.py", line 240, in __init__
    self.open()
  File "C:\Users\wwade\AppData\Local\Programs\Python\Python37\lib\site-packages\serial\serialwin32.py", line 62, in open
    raise SerialException("could not open port {!r}: {!r}".format(self.portstr, ctypes.WinError()))
serial.serialutil.SerialException: could not open port 'COM8': PermissionError(13, 'Access is denied.', None, 5)

2019-02-27 07:36:33,204: Will retry in 10 seconds
2019-03-01 15:44:03,702: http-jsonrpc listening at 127.0.0.1:5383
2019-03-01 15:44:03,712: serial device opened: /dev/cu.SLAB_USBtoUART
2019-03-01 15:45:16,891: relaykeysd exit!
2019-03-01 15:57:31,428: http-jsonrpc listening at 127.0.0.1:5383
2019-03-01 15:57:31,433: Traceback (most recent call last):
  File "/Users/willwade/.pyenv/versions/3.7.1/envs/relayKeys371-3.7.1/lib/python3.7/site-packages/serial/serialposix.py", line 265, in open
    self.fd = os.open(self.portstr, os.O_RDWR | os.O_NOCTTY | os.O_NONBLOCK)
OSError: [Errno 16] Resource busy: '/dev/cu.SLAB_USBtoUART'

During handling of the above exception, another exception occurred:

Traceback (most recent call last):
  File "relaykeysd.py", line 265, in do_main
    with SerialCls(devicepath, BAUD, rtscts=1) as ser:
  File "/Users/willwade/.pyenv/versions/3.7.1/envs/relayKeys371-3.7.1/lib/python3.7/site-packages/serial/serialutil.py", line 240, in __init__
    self.open()
  File "/Users/willwade/.pyenv/versions/3.7.1/envs/relayKeys371-3.7.1/lib/python3.7/site-packages/serial/serialposix.py", line 268, in open
    raise SerialException(msg.errno, "could not open port {}: {}".format(self._port, msg))
serial.serialutil.SerialException: [Errno 16] could not open port /dev/cu.SLAB_USBtoUART: [Errno 16] Resource busy: '/dev/cu.SLAB_USBtoUART'

2019-03-01 15:57:31,433: Will retry in 10 seconds
2019-03-01 15:57:41,137: http-jsonrpc listening at 127.0.0.1:5383
2019-03-01 15:57:41,146: serial device opened: /dev/cu.SLAB_USBtoUART
2019-03-01 15:58:01,279: relaykeysd exit!
2019-03-06 15:16:26,852: http-jsonrpc listening at 127.0.0.1:5383
2019-03-06 15:16:26,877: serial device opened: /dev/cu.usbmodem2101
2019-03-06 15:16:30,800: relaykeysd exit!
2019-03-11 10:02:43,082: http-jsonrpc listening at 127.0.0.1:5383
2019-03-11 10:02:43,092: serial device opened: /dev/cu.SLAB_USBtoUART
2019-03-11 10:15:58,921: relaykeysd exit!
2019-03-11 10:16:00,246: http-jsonrpc listening at 127.0.0.1:5383
2019-03-11 10:16:00,909: serial device opened: /dev/cu.SLAB_USBtoUART
2019-03-11 10:17:00,371: relaykeysd exit!
2019-03-11 10:17:01,428: http-jsonrpc listening at 127.0.0.1:5383
2019-03-11 10:17:02,363: serial device opened: /dev/cu.SLAB_USBtoUART
2019-03-11 10:20:51,741: relaykeysd exit!
2019-03-11 10:21:18,619: http-jsonrpc listening at 127.0.0.1:5383
2019-03-11 10:21:18,628: serial device opened: /dev/cu.SLAB_USBtoUART
2019-03-11 10:24:40,942: relaykeysd exit!
2019-03-13 10:23:37,258: http-jsonrpc listening at 127.0.0.1:5383
2019-03-13 10:23:37,259: serial device opened: /dev/ttys004
2019-03-13 10:46:13,202: relaykeysd exit!
2019-03-13 10:46:14,693: http-jsonrpc listening at 127.0.0.1:5383
2019-03-13 10:46:14,694: serial device opened: /dev/ttys004
2019-03-13 13:26:36,240: relaykeysd exit!
2019-03-13 13:32:28,067: http-jsonrpc listening at 127.0.0.1:5383
2019-03-13 13:32:28,070: Traceback (most recent call last):
  File "/Users/willwade/.pyenv/versions/3.7.1/envs/relayKeys371-3.7.1/lib/python3.7/site-packages/serial/serialposix.py", line 265, in open
    self.fd = os.open(self.portstr, os.O_RDWR | os.O_NOCTTY | os.O_NONBLOCK)
FileNotFoundError: [Errno 2] No such file or directory: '/dev/ttys004'

During handling of the above exception, another exception occurred:

Traceback (most recent call last):
  File "relaykeysd.py", line 265, in do_main
    with SerialCls(devicepath, BAUD, rtscts=1) as ser:
  File "/Users/willwade/.pyenv/versions/3.7.1/envs/relayKeys371-3.7.1/lib/python3.7/site-packages/serial/serialutil.py", line 240, in __init__
    self.open()
  File "/Users/willwade/.pyenv/versions/3.7.1/envs/relayKeys371-3.7.1/lib/python3.7/site-packages/serial/serialposix.py", line 268, in open
    raise SerialException(msg.errno, "could not open port {}: {}".format(self._port, msg))
serial.serialutil.SerialException: [Errno 2] could not open port /dev/ttys004: [Errno 2] No such file or directory: '/dev/ttys004'

2019-03-13 13:32:28,071: Will retry in 10 seconds
2019-03-13 13:34:44,729: http-jsonrpc listening at 127.0.0.1:5383
2019-03-13 13:34:44,731: serial device opened: /dev/ttys004
2019-03-13 13:35:39,251: Traceback (most recent call last):
  File "/Users/willwade/.pyenv/versions/3.7.1/envs/relayKeys371-3.7.1/lib/python3.7/site-packages/serial/serialposix.py", line 501, in read
    'device reports readiness to read but returned no data '
serial.serialutil.SerialException: device reports readiness to read but returned no data (device disconnected or multiple access on port?)

During handling of the above exception, another exception occurred:

Traceback (most recent call last):
  File "relaykeysd.py", line 301, in do_main
    msg = ser.readline()
  File "/Users/willwade/.pyenv/versions/3.7.1/envs/relayKeys371-3.7.1/lib/python3.7/site-packages/serial/serialposix.py", line 509, in read
    raise SerialException('read failed: {}'.format(e))
serial.serialutil.SerialException: read failed: device reports readiness to read but returned no data (device disconnected or multiple access on port?)

2019-03-13 13:35:39,252: Will retry in 10 seconds
2019-03-13 13:35:47,836: http-jsonrpc listening at 127.0.0.1:5383
2019-03-13 13:35:47,844: Traceback (most recent call last):
  File "/Users/willwade/.pyenv/versions/3.7.1/envs/relayKeys371-3.7.1/lib/python3.7/site-packages/serial/serialposix.py", line 265, in open
    self.fd = os.open(self.portstr, os.O_RDWR | os.O_NOCTTY | os.O_NONBLOCK)
OSError: [Errno 16] Resource busy: '/dev/cu.SLAB_USBtoUART'

During handling of the above exception, another exception occurred:

Traceback (most recent call last):
  File "relaykeysd.py", line 265, in do_main
    with SerialCls(devicepath, BAUD, rtscts=1) as ser:
  File "/Users/willwade/.pyenv/versions/3.7.1/envs/relayKeys371-3.7.1/lib/python3.7/site-packages/serial/serialutil.py", line 240, in __init__
    self.open()
  File "/Users/willwade/.pyenv/versions/3.7.1/envs/relayKeys371-3.7.1/lib/python3.7/site-packages/serial/serialposix.py", line 268, in open
    raise SerialException(msg.errno, "could not open port {}: {}".format(self._port, msg))
serial.serialutil.SerialException: [Errno 16] could not open port /dev/cu.SLAB_USBtoUART: [Errno 16] Resource busy: '/dev/cu.SLAB_USBtoUART'

2019-03-13 13:35:47,844: Will retry in 10 seconds
2019-03-13 13:35:57,616: http-jsonrpc listening at 127.0.0.1:5383
2019-03-13 13:35:57,627: serial device opened: /dev/cu.SLAB_USBtoUART
2019-03-13 13:43:29,231: relaykeysd exit!
2019-03-13 14:23:58,948: http-jsonrpc listening at 127.0.0.1:5383
2019-03-13 14:23:58,959: serial device opened: /dev/cu.SLAB_USBtoUART
2019-03-13 14:24:47,327: Traceback (most recent call last):
  File "/Users/willwade/.pyenv/versions/3.7.1/envs/relayKeys371-3.7.1/lib/python3.7/site-packages/serial/serialposix.py", line 493, in read
    buf = os.read(self.fd, size - len(read))
OSError: [Errno 6] Device not configured

During handling of the above exception, another exception occurred:

Traceback (most recent call last):
  File "relaykeysd.py", line 302, in do_main
    logging.debug("response: {}".format(str(ser.readline(), "utf8")))
  File "/Users/willwade/.pyenv/versions/3.7.1/envs/relayKeys371-3.7.1/lib/python3.7/site-packages/serial/serialposix.py", line 509, in read
    raise SerialException('read failed: {}'.format(e))
serial.serialutil.SerialException: read failed: [Errno 6] Device not configured

2019-03-13 14:24:47,330: Will retry in 10 seconds
2019-03-13 14:28:40,359: http-jsonrpc listening at 127.0.0.1:5383
2019-03-13 14:28:40,385: serial device opened: /dev/cu.usbmodem2201
2019-03-13 14:36:00,189: Traceback (most recent call last):
  File "/Users/willwade/.pyenv/versions/3.7.1/envs/relayKeys371-3.7.1/lib/python3.7/site-packages/serial/serialposix.py", line 537, in write
    n = os.write(self.fd, d)
OSError: [Errno 6] Device not configured

During handling of the above exception, another exception occurred:

Traceback (most recent call last):
  File "relaykeysd.py", line 282, in do_main
    blehid_send_keyboardcode(ser, key, modifiers, down, keys)
  File "/Users/willwade/bin/RelayKeys/blehid.py", line 201, in blehid_send_keyboardcode
    ser.write(atcmd.encode());
  File "/Users/willwade/.pyenv/versions/3.7.1/envs/relayKeys371-3.7.1/lib/python3.7/site-packages/serial/serialposix.py", line 571, in write
    raise SerialException('write failed: {}'.format(e))
serial.serialutil.SerialException: write failed: [Errno 6] Device not configured

2019-03-13 14:36:00,190: Will retry in 10 seconds
2019-03-13 14:36:10,225: serial device opened: /dev/cu.usbmodem2201
2019-03-13 14:36:10,435: relaykeysd exit!
2019-03-13 14:36:15,498: http-jsonrpc listening at 127.0.0.1:5383
2019-03-13 14:36:15,519: serial device opened: /dev/cu.usbmodem2201
